<?xml version="1.0" encoding="UTF-8"?>
<!-- Generated by org.testng.reporters.JUnitReportReporter -->
<testsuite hostname="AJIT-LAP" failures="0" tests="4" name="c_pack.new_exception" time="5.040" errors="1" timestamp="2023-02-13T15:24:35 IST" skipped="0">
  <testcase classname="c_pack.new_exception" name="program_003" time="5.034">
    <error message="Method c_pack.new_exception.program_003() didn&#039;t finish within the time-out 5000" type="org.testng.internal.thread.ThreadTimeoutException">
      <![CDATA[org.testng.internal.thread.ThreadTimeoutException: Method c_pack.new_exception.program_003() didn't finish within the time-out 5000
at java.base@18/java.lang.Thread.sleep(Native Method)
at app//c_pack.new_exception.program_003(new_exception.java:23)
at java.base@18/java.lang.invoke.LambdaForm$DMH/0x0000000800d1c000.invokeVirtual(LambdaForm$DMH)
at java.base@18/java.lang.invoke.LambdaForm$MH/0x0000000800d1c800.invoke(LambdaForm$MH)
at java.base@18/java.lang.invoke.Invokers$Holder.invokeExact_MT(Invokers$Holder)
at java.base@18/jdk.internal.reflect.DirectMethodHandleAccessor.invokeImpl(DirectMethodHandleAccessor.java:154)
at java.base@18/jdk.internal.reflect.DirectMethodHandleAccessor.invoke(DirectMethodHandleAccessor.java:104)
at java.base@18/java.lang.reflect.Method.invoke(Method.java:577)
at app//org.testng.internal.invokers.MethodInvocationHelper.invokeMethod(MethodInvocationHelper.java:139)
at app//org.testng.internal.invokers.InvokeMethodRunnable.runOne(InvokeMethodRunnable.java:47)
at app//org.testng.internal.invokers.InvokeMethodRunnable.call(InvokeMethodRunnable.java:76)
at app//org.testng.internal.invokers.InvokeMethodRunnable.call(InvokeMethodRunnable.java:11)
at java.base@18/java.util.concurrent.FutureTask.run(FutureTask.java:264)
at java.base@18/java.util.concurrent.ThreadPoolExecutor.runWorker(ThreadPoolExecutor.java:1136)
at java.base@18/java.util.concurrent.ThreadPoolExecutor$Worker.run(ThreadPoolExecutor.java:635)
at java.base@18/java.lang.Thread.run(Thread.java:833)
]]>
    </error>
  </testcase> <!-- program_003 -->
  <system-out/>
  <testcase classname="c_pack.new_exception" name="program_001" time="0.002"/>
  <system-out/>
  <testcase classname="c_pack.new_exception" name="program_004" time="0.003"/>
  <system-out/>
  <testcase classname="c_pack.new_exception" name="program_002" time="0.001"/>
  <system-out/>
</testsuite> <!-- c_pack.new_exception -->
